File: MDSdata/MDS5_Nanoindentation/CuCr.csv
,Surface Displacement,Displacement Into Surface,Load On Sample,Modulus,Stiffness^2/Load,Hardness,Row Number,Contact Depth,Contact Area,Time,Unnamed: 10
1,15775.263307491818,953.9901609423105,54.59327881343719,283.68482495864043,26474.41006869151,2.7566735143660184,0.0,919.9322734232803,19804042.273752026,117.69199999997215,1.0
3,15458.918937365168,944.8462278365535,57.43700862205634,375.3789286235843,38332.1611170278,2.9254221815659567,0.0,915.8143239372167,19633750.295593485,123.74399999995805,3.0
5,16406.843595787894,989.0108210598846,63.35958000977586,424.1535896273473,45566.67148362938,2.9409042571510047,0.0,961.0439580309427,21544251.17911024,131.01599999996253,5.0
7,16803.967254075593,922.4212184098609,29.051249355317577,193.31049033123145,25253.124241999747,1.5400098029850433,0.0,896.9830339196227,18864327.55103685,137.7719999999948,7.0
10,15470.87745187694,933.8322672047044,59.6797053851806,380.0751781138015,36614.632905473765,3.1195246127757272,0.0,903.5528678088857,19131025.650757115,145.59200000003213,10.0
12,15350.890179226411,820.7747771837701,71.01300517414175,297.8744406736522,15629.228821670615,5.042476199818594,0.0,770.2200891795935,14082962.885714063,151.62200000006092,12.0
14,16427.33211205352,923.8672300902342,30.920122619203806,173.71205080510555,19644.314049349185,1.649217110007719,0.0,894.1119917784705,18748363.954979274,158.8620000000955,14.0
17,16148.079553475625,838.9648619246357,44.75614667504236,210.54467073298778,15127.730083694592,2.9683759514200805,0.0,798.1704455654989,15077654.383243095,167.18800000013525,17.0
19,16909.28169471897,857.4445086624161,46.61017466796607,205.8188282201503,14554.453863235618,2.9701439979127597,0.0,815.001743390205,15692900.64748407,174.24600000016895,19.0
21,17304.19453634536,845.9936603239213,27.58266977131381,181.22985940286836,19968.55113511937,1.7448333407313774,0.0,818.1192212961699,15808197.337490154,180.90800000020076,21.0
24,16649.10176580136,956.7200813228014,67.67690074776749,393.9081345391267,35527.531839695344,3.388521811374918,0.0,923.986089035837,19972396.376668766,189.7100000002428,24.0
26,18051.866609940527,970.9717713610664,22.70079976566087,149.35677856199138,23000.887260151645,1.0831019638958053,0.0,947.4099126318982,20959060.663142417,197.59200000028042,26.0
28,15572.59308039379,960.1665244155139,57.909771741705185,267.3629457414212,22828.332722622512,2.9091461964789302,1.0,922.3919053816371,19906105.71988303,212.86000000035332,28.0
30,15409.403646482195,977.2290031504075,61.107026870974416,392.5971180098352,41167.19183055708,2.910073715503824,1.0,948.3334362850572,20998446.377979435,218.83000000038183,30.0
32,16455.70756258993,1106.6757831687519,23.77298054927277,153.94517726872968,30124.332188534212,0.8720264257898886,1.0,1085.6067616407622,27261766.2105125,226.18200000041693,32.0
39,16092.739096155894,991.9916209663602,54.95066865026945,254.62988730234423,23826.76819808735,2.5767339258628454,1.0,955.9739866672733,21325705.420620278,244.04400000050222,39.0
41,15810.758572556188,1151.5304862439675,46.448845122557465,197.15502895901838,25033.98145168756,1.606144245113724,1.0,1119.2244437089353,28919472.994947992,250.02000000053076,41.0
44,16397.46550688565,971.6252182714202,49.77939085793003,246.61204039080528,24050.61951599734,2.4236616328196297,1.0,937.5041265283849,20538919.37053024,259.1460000005743,44.0
46,18124.12617614089,996.0916892003196,26.941094482327372,153.49226568593835,21250.140652596823,1.2298333339641891,1.0,969.3869724184042,21906297.169134837,267.38400000061364,46.0
48,17901.565526730086,988.3059872185676,27.265834031188238,162.5701390689327,22889.307892961773,1.262085984930798,1.0,962.4206202468748,21603784.810813237,273.3840000006423,48.0
52,18146.89457080667,825.0458700243998,30.61114236869693,295.53708921435356,38880.372921023234,2.002113023637764,1.0,804.0015052489584,15289417.73380887,283.93200000069265,52.0
54,15831.349618166347,808.1525241067174,32.4443665049365,226.5194847740465,22532.143528627752,2.2505331149893153,2.0,779.6928673260368,14416302.647957498,299.5460000007672,54.0
56,15391.48047626279,860.60787596702,28.435964264301443,168.65302309407195,17614.4246557805,1.7478367944763524,2.0,830.473582587052,16269233.119572122,305.31000000079473,56.0
59,15807.556982248796,982.7850408008953,62.690004570950926,442.4019104193542,48389.429125732364,2.940736262450085,2.0,955.7899268606689,21317792.20443268,315.21600000084203,59.0
61,15283.685516249236,963.2428842289276,60.47704763046256,402.8364394045638,42008.523690802846,2.9610236102909884,2.0,934.7859674028119,20424371.970650822,320.860000000869,61.0
63,15322.645808924322,969.6046106005246,65.67145947484411,368.0417368246451,33997.13796190403,3.203090252240707,2.0,936.6414824682132,20502531.71258723,327.18200000089917,63.0
65,16951.150126614717,952.4751728331247,28.630700091298525,189.3216704686515,26392.643721799654,1.4222685917676259,2.0,927.7729633901151,20130304.681562066,335.1420000009372,65.0
68,16749.489908979696,806.4731206457153,28.987963138499364,252.41136881236218,30371.101457802255,1.9930755510685445,2.0,783.3023839384256,14544337.329790682,343.40800000097664,68.0
70,17162.35573198466,913.2967672098667,60.233505560247,289.62111580606336,22490.75978090216,3.3528095336121195,2.0,874.4836727047278,17965084.194733538,350.27800000100945,70.0
72,18428.79061546544,859.0749511245342,30.548945223777892,249.49349203681024,32033.7948477267,1.8543341962744346,2.0,835.9140646244948,16474347.11884953,357.9920000010463,72.0
74,18280.895332177548,979.6051357128866,27.56953005070696,165.13312923655633,22848.776425904314,1.2991176497871593,2.0,953.5529316712801,21221734.6559981,364.1120000010755,74.0
79,15913.83324272748,931.2539117510487,54.23325549741658,385.10103858466806,41120.626841351084,2.8320354839617776,3.0,904.0166002521239,19149920.897724364,386.832000001184,79.0
81,16459.66930666297,999.1724159494767,26.944994336236146,153.42320654984908,21363.561175610335,1.222340968778876,3.0,972.5367544260278,22043762.767073344,393.6400000012165,81.0
89,16167.274369719178,914.9306458378002,41.07734585592274,262.38255797530934,28941.528928142023,2.226457804213961,3.0,886.6752292011917,18449640.40107864,413.86600000131307,89.0
91,17368.56094989296,1007.6880969017687,28.726739840852208,177.49928074367617,26333.581860135662,1.276755112478879,3.0,982.9167588352149,22499804.042356968,421.3460000013488,91.0
98,18585.909713269866,855.4692353716125,26.600471129995803,237.62504421674296,33863.978170317976,1.6201042194982966,3.0,834.4490307212067,16418987.624285841,440.8260000014418,98.0
100,18824.306487434926,994.8583642718881,25.46912062029775,149.27025133581338,21388.14108509478,1.1635871962490851,3.0,968.9773246050038,21888450.390653547,447.3360000014729,100.0
106,16930.245152263717,980.5172883973509,26.61796582223626,182.10036090142236,28230.177599442643,1.2443636088733774,4.0,957.4873970104668,21390826.308666844,472.86000000159476,106.0
114,16395.075304714464,992.5301277897252,29.311461137921043,163.91850489785057,21709.967700715468,1.34986697214979,4.0,964.9719556417829,21714333.147391394,492.79400000168994,114.0
116,16416.309393546424,876.5706763568747,42.83096641483824,235.3161350357538,21095.70772217019,2.5593817454148433,4.0,842.7764000687456,16734887.826550422,498.97800000171947,116.0
118,17819.978975884984,977.7214705579054,25.962211881571797,131.75431965569842,16117.14668425712,1.2381816052496637,4.0,947.619978079935,20968016.138744727,506.82400000175693,118.0
127,18274.528969599123,960.3273935498805,37.64534739246919,197.46052348055252,21613.19255150602,1.8652276035569741,4.0,929.0264480276837,20182709.777980883,530.2180000013508,127.0
131,17660.028930174325,1042.8927210707582,27.690406607216715,159.52743751602338,24285.08205778113,1.151090533874663,5.0,1017.5673310576265,24055802.556214746,552.3900000008265,131.0
143,17483.74200205778,855.2208221169338,47.59040295513034,314.0460979350531,28869.269694950926,2.9641073005564764,5.0,824.7697172024709,16055560.116260229,582.4540000001156,143.0
145,17546.49284426803,1004.449189771803,24.146455290683196,199.76022086010212,38513.09566476527,1.0674102120455535,5.0,985.6697020231527,22621532.95724016,588.7919999999657,145.0
147,17043.950579887274,893.6374781992023,29.93388914953849,249.466212393699,35437.09274906906,1.6759506478263584,5.0,871.8396214688121,17860841.659246683,594.5459999998296,147.0
152,19058.66019864767,973.3634401784151,30.56336472561661,158.06957958271965,18698.40401496754,1.471284636628493,5.0,943.0413192259867,20773250.780116733,611.7499999994228,152.0
155,18200.654257711638,812.7680634498533,35.77086177423653,294.8717172112257,31874.478308927737,2.433548371240931,5.0,787.643158801185,14699055.172672002,619.565999999238,155.0
157,17894.66554020638,992.7896894606823,26.418833785447422,163.62562206525647,24157.24854483721,1.2093574989564078,6.0,967.9872527080466,21845346.647492625,637.2779999988192,157.0
169,17015.77276414359,875.6032933523443,92.11065376278451,451.03585830913744,25851.50418509279,5.656926559710449,6.0,830.8347167036991,16282808.834537746,666.7379999981225,169.0
171,17956.801935903164,989.889123239321,28.42393351981351,177.20228847480433,25607.696425103233,1.3091773320365352,6.0,964.9018942727791,21711293.668366298,674.0999999979484,171.0
176,17512.146177634884,873.0992274145852,37.60018243646162,223.452983844526,22033.22741043632,2.2501939276239065,6.0,842.1166758627969,16709751.979539627,687.0559999976421,176.0
179,18971.849388679624,953.9917781581576,26.969563284692885,168.6565811279232,23006.37891496543,1.3382489481933897,6.0,928.3130159143749,20152874.6359945,697.9079999973854,179.0
182,18813.89821369882,999.678807820447,26.669787299285698,168.80428415024798,25635.775051857243,1.2028069132203059,6.0,975.4881424797296,22172958.108365037,706.5039999971822,182.0
184,17870.669075408125,973.269185642936,25.14865951361777,137.74772833871106,17917.835373469537,1.2053765916423829,7.0,945.1711529884304,20863736.43555789,723.5839999967783,184.0
187,16988.32587723041,976.0791812131679,29.39002498137798,173.17431621692006,23069.8214439935,1.3968561069885133,7.0,949.3097511801063,21040123.48468736,731.4079999965933,187.0
189,16162.720535427521,870.5721440958753,30.34636976901751,195.70360067359618,21891.588207068864,1.8138890025281467,7.0,842.6482487955033,16730003.724991774,736.8139999964654,189.0
191,16234.887441502387,801.0621308507792,41.23090209750487,313.7789786357362,29389.425713688717,2.9078135803972978,7.0,772.9704884096933,14179348.48900164,743.0939999963169,191.0
196,17626.793353647525,863.4753431545772,53.75623626290633,416.20622810209835,39971.666506932575,3.262599551294826,7.0,835.9711086163354,16476504.522772992,758.1099999959619,196.0
198,17735.724398587165,957.2044912470253,26.75451190028564,181.16348184740696,26504.343795033576,1.3137452494117896,7.0,933.3757417674215,20365068.427280392,764.5359999958099,198.0
203,18010.02092397416,1105.1255614701324,24.159678434024947,149.30699240521048,27968.325056996953,0.8902115289190008,7.0,1083.0824138587836,27139255.83884817,778.2719999954851,203.0
208,18787.643626142282,1024.3431512354512,26.918683886940332,171.89797699813127,27540.63365743722,1.1552745847782921,7.0,1000.8953993210289,23300680.41106113,792.44199999515,208.0
210,17942.87040810536,1015.4582468544352,26.5635383835919,146.49254660916225,20620.62052268579,1.1676906346738998,8.0,988.5395915939076,22748780.879800655,809.483999994747,210.0
212,17266.53656879686,898.8033648121238,30.688152922809177,273.4542179726001,40631.63512762183,1.6943753538790103,8.0,878.1916327514383,18111779.572662808,815.1339999946134,212.0
214,16862.165054811943,1049.6838713501184,74.93474033663473,263.44920353422407,20292.671737473298,3.19615670799653,8.0,1004.1081814273443,23445264.79229068,821.0139999944744,214.0
218,15644.758101457854,1011.01552232097,76.53131454764525,292.56391918528004,21808.719615689963,3.513118267274307,8.0,966.5866013891387,21784440.125616085,830.8339999942422,218.0
220,15329.282944484614,1022.0793554948583,61.41629469257896,348.143427907952,37334.49081278956,2.683393616135012,8.0,991.6601439684081,22887545.95050392,836.5039999941081,220.0
222,17509.44902410248,1029.6756621479728,74.09231392031748,393.4314458223404,37459.38415553227,3.2080775387512657,8.0,996.3201567144864,23095549.601072825,845.0559999939059,222.0
229,17992.778299203415,934.7188861211697,48.231222592686144,358.11121393483285,41971.53559086115,2.490557413205687,8.0,909.2946467153545,19365633.707920022,863.6679999934657,229.0
231,18515.836232699676,939.1986418239899,29.840761774720523,218.70486906287863,31498.638442926123,1.5189134023027127,8.0,916.1141496312632,19646124.47917119,870.4459999933055,231.0
233,18671.485919652576,1020.0339934949793,26.947910150801277,162.1202964176769,24586.367674446465,1.1693277278105514,8.0,995.2039990295607,23045643.671905845,876.7539999931563,233.0
235,17697.533138592713,969.1462140985936,26.19747715700774,138.06411675707386,17081.101850297877,1.2695756339061073,9.0,939.7742453519702,20634829.826093845,893.6999999927556,235.0
237,17744.415190562937,968.6731241311096,26.740174083831466,144.4967870300052,18141.14585999441,1.2955987177599508,9.0,939.8785260521211,20639240.92952514,900.0319999926058,237.0
239,17140.705274112523,865.7990508448956,29.01387258592168,218.9524096881938,27565.24629769117,1.738918728894719,9.0,841.4667501647532,16685007.817681795,905.5559999924752,239.0
250,16945.222178406202,919.5000376688845,30.56730101629138,207.03192660769147,26779.832376445585,1.6302255872010634,9.0,894.1612470333853,18750350.41547374,933.219999991821,250.0
256,17452.09976267285,977.1363269244215,57.595398875126975,375.4156763420917,40945.75875537307,2.739087780341096,9.0,949.007559845031,21027219.094071776,949.5559999914348,256.0
258,17990.066550335872,1012.1155530131887,75.13148508783789,289.32691065960216,21899.096174987335,3.4378848271588893,9.0,968.1857602354486,21853985.47802065,956.7379999912649,258.0
260,18165.52590821471,819.9146824846007,53.0714711524418,366.37668942218704,30010.750599840336,3.6041182239123013,9.0,788.3752846145433,14725230.376830498,963.3139999911094,260.0
262,16472.63634139838,993.1942641399397,60.86487506320563,386.63710270998956,41756.609367759476,2.8052885546996817,10.0,964.5602643490037,21696475.737313762,979.5419999907257,262.0
264,17436.216506818055,884.667760289784,30.054454549111295,202.75341667709986,24308.093632364806,1.7340837025784759,10.0,858.2959320593249,17331605.449276857,986.8839999905521,264.0
278,17222.709446991474,949.415650938228,32.926472998457584,154.4496593990763,15730.414161073193,1.679546973547608,10.0,915.1022479232023,19604377.559568305,1022.6139999897072,278.0
282,16759.898572228038,978.2425859288817,61.824233668590644,424.7225587743353,45821.74719239925,2.9301598319811335,10.0,950.693651086498,21099270.07865307,1032.8679999894648,282.0
284,17470.914069037004,960.9394784707993,59.83152928135485,389.40471100435775,40176.68238597137,2.9463265142573127,10.0,931.9967627294809,20307161.813814353,1039.9539999892972,284.0
287,15542.570017263444,969.3863845177592,60.70987116511823,377.3730906442732,38398.60284928172,2.9433712755329577,11.0,939.5646288491994,20625964.406792503,1058.955999988848,287.0
289,17512.482407857842,959.7501346289681,26.986727294351716,171.48560182813085,23970.606512456627,1.3218471399900429,11.0,934.5851388319956,20415921.386004593,1067.32999998865,289.0
303,17987.610627177197,982.8589735929054,26.44996725578354,138.77655199413172,17565.837732842905,1.2458511257056633,11.0,953.7558636817422,21230439.745199893,1103.0119999878061,303.0
305,17576.72432560705,985.2469008309918,27.851640737491387,163.62021056757786,22498.42095222968,1.2984499063250141,11.0,958.858647999446,21449915.473689336,1108.8699999876676,305.0
314,16429.92698255035,844.4274127571019,49.63169865427786,336.8260403411327,30053.318374572376,3.1705330776175917,12.0,813.9488406431794,15654054.835337726,1142.939999986862,314.0
324,16770.321852577352,972.2932825722839,28.041079940630915,163.66407394098687,21754.525285891366,1.3434753033058062,12.0,945.3665395436096,20872047.198509697,1168.899999986248,324.0
326,17117.71718629292,918.4850625897013,27.07471771071283,199.68352960610727,28526.003278672873,1.4401826785479284,12.0,895.3791690439396,18799502.39230141,1175.6859999860876,326.0
329,18024.924569824354,1001.8202957640261,27.397379243046718,141.79591173502774,18301.090088261833,1.2422105475226382,12.0,972.8016397334933,22055342.629062183,1185.397999985858,329.0
331,17994.269395341937,997.4134560277498,26.931229020323947,153.59751400782832,21342.0836263843,1.2260049332567426,12.0,970.7712034469183,21966656.323954746,1191.5799999857118,331.0
333,17538.496409913205,964.0604319191373,28.523512353588934,188.04107412084778,26834.89466371196,1.3827690740190246,12.0,939.6085202949506,20627820.57360107,1197.3779999855747,333.0
335,16460.392946065047,937.1096153319439,64.95363221134856,405.54451514482435,37168.86704512736,3.379319751778735,12.0,905.7570325940876,19220919.292162172,1202.5819999854516,335.0
337,17243.5704594068,897.2379992083243,45.637784374547245,293.2724882067438,29838.58571096057,2.57748345479391,12.0,867.9064891473291,17706334.56042741,1209.753999985282,337.0
339,14807.920057009618,938.8543351786916,58.61551260521736,365.3267069738846,35513.90106278164,3.032617683386211,13.0,908.3846226497174,19328355.47531579,1225.2159999849164,339.0
341,17125.896414742656,908.1981701719294,27.82518435428374,184.50753279252118,23602.845924124536,1.5220938625805625,13.0,882.4469327552625,18280859.701456808,1233.94799998471,341.0
351,17475.387400082058,971.2861691896162,27.419027273213487,158.22300247137173,20924.726078505548,1.3169704619389728,13.0,944.1369468347983,20819773.917210344,1259.8879999840965,351.0
355,17158.320941083763,861.5883189220963,36.18153122394434,179.08325964769767,15154.758872757278,2.252617667247452,13.0,824.9420116042254,16061993.897151556,1269.9939999838575,355.0
357,18042.613051516113,932.0569562066344,28.92849746868731,198.5106740153581,27130.478509556673,1.4992839578135926,13.0,907.5665789495928,19294875.60906993,1277.0919999836897,357.0
365,14869.338126827897,952.8288369463247,60.66578488040083,396.9205761896017,40048.36199382424,3.0396834333563736,14.0,923.6383866277906,19957928.583837617,1306.4179999829962,365.0
367,16751.73391173215,908.1125911560171,53.97978372616258,281.46571819425145,23882.00386833104,3.018140938021573,14.0,872.45586617786,17885110.349269163,1314.6779999828009,367.0
383,16917.833732492745,968.9687691060245,56.357763792237606,211.77093226886197,16088.740340963976,2.8182963073384615,14.0,924.5795895189797,19997103.7983088,1354.6879999818548,383.0
392,15075.375486664021,986.8445080173326,63.16433461624137,384.8655359882061,39347.50452576317,2.9569909841719695,15.0,956.7949125954746,21361016.977848157,1388.4939999810554,392.0
394,16589.354148335548,924.9856046674121,31.547408714669217,283.73220484926753,44405.16816980813,1.6439661548342344,15.0,904.9949806985504,19189816.421646606,1396.3599999808694,394.0
407,15947.542345010945,923.7919784399386,52.0528375423743,321.00858305731833,31838.225634843304,2.780253192990095,15.0,893.4664037481083,18722337.11433768,1428.3779999801122,407.0
409,16383.285082912855,976.1597493253366,56.849003681014196,356.04359964778723,38190.936357898565,2.7134119406655297,15.0,947.2234799287669,20951114.28862903,1435.107999979953,409.0
411,17391.541627981875,954.5652217839132,32.60802773478001,181.21006971969075,21394.37877109014,1.6282446399625266,15.0,925.2850453683228,20026491.67973338,1442.599999979776,411.0
413,17054.31533450583,909.238325800825,29.84124236858443,204.99026303007008,26393.58014632047,1.6267974090480115,15.0,884.0197497132829,18343551.694028873,1448.5259999796358,413.0
419,16285.535066187598,889.842642111184,55.97165477948059,291.39251373847736,23300.92147929176,3.267453665182979,16.0,853.0840568148934,17130053.097890265,1476.0739999789844,419.0
423,15705.771182021686,991.0582920587111,32.08451112516729,191.5796863876522,25905.77718804594,1.4784826095063965,16.0,964.6639607614574,21700972.956238534,1486.5239999787373,423.0
425,14829.061833504333,963.966940409057,72.1829270542364,409.04351370189664,35648.16230048796,3.5676564496866514,16.0,930.2180161254682,20232589.116190337,1491.7659999786133,425.0
427,14942.741793800295,948.2959607198524,51.99264072694928,203.4120873910222,15645.148369222823,2.709011014240726,16.0,905.0602742988834,19192480.37517545,1498.2659999784596,427.0
429,15612.340081778884,962.0050283300844,81.1868260793372,336.6750259733235,23111.689241026033,4.119992559633451,16.0,917.5533461663973,19705575.897098288,1505.0919999782982,429.0
431,15429.5489332138,973.034718665797,59.45024984035229,232.7319271930691,18035.64294904945,2.9398206790435624,16.0,929.9748906455637,20222406.85091506,1511.1399999781552,431.0
433,15967.92136946041,985.9438817580359,62.53183997513984,355.1223192903921,35083.49600395197,2.9422673000178454,16.0,954.2802711847398,21252943.257317435,1518.1099999779904,433.0
435,17000.26216813276,1027.4031827169333,34.648679751130096,162.47847172764799,19208.306754679936,1.5024739823056141,16.0,995.5494693703396,23061084.690438457,1525.4659999778164,435.0
437,17713.1020189446,969.1732438203887,26.34869582484821,158.1238848699173,21702.301782376133,1.2683979818325752,16.0,943.040324588527,20773208.568796165,1532.3499999776536,437.0
439,17013.865004900195,952.1600464371757,40.81579489502992,246.71132898684786,28530.50172004818,2.0444346135253593,16.0,923.7925709436258,19964343.503580406,1537.8219999775242,439.0
444,14852.606290232105,990.9410162004255,65.83366879583902,375.1207783805061,36516.896303404006,3.0677154578535024,17.0,959.0962280991301,21460161.380776558,1560.5619999769865,444.0
446,16539.196511137277,944.2815838385488,65.94762692026623,288.68074664444157,21736.383908146017,3.451434890993728,17.0,902.9704417566372,19107307.25135561,1568.657999976795,446.0
448,16357.818780678344,969.2406365681813,29.629108427593085,176.8839311137908,23409.11266517816,1.4277198995976474,17.0,942.558040661558,20752745.994465027,1574.575999976655,448.0
454,15849.272667231126,823.304671525729,31.548263962850854,201.5113655186707,19705.612732834466,2.1170860119047914,17.0,793.29549870641,14901739.365074806,1589.9399999762918,454.0
456,16198.668772906864,886.6563855480645,31.68575680975862,216.6082612986149,25875.871562221815,1.8195826366701957,17.0,860.4114317654029,17413749.818883188,1596.6219999761338,456.0
458,15769.327935821646,897.33108954499,66.427687941537,355.36411640854504,27073.783079268997,3.816633011376579,17.0,860.1808721648391,17404787.870232757,1602.495999975995,458.0
461,16654.656960809996,885.3531355119818,27.436602731474945,147.12953743226439,15161.052690974704,1.6003537660167975,17.0,853.4479148730402,17144086.08526808,1612.889999975749,461.0
464,17740.87747565612,981.0795290524884,27.829887501390445,143.32465836530903,17584.715628455662,1.3175302895060887,17.0,951.2429302896768,21122768.655150402,1623.6679999754942,464.0
470,15777.887443338335,915.7410047700528,29.779427739894683,195.90172855169936,24808.454471676505,1.6033625961349627,18.0,889.7561925528182,18573108.67278583,1649.0339999748944,470.0
472,16941.611319225296,968.3481373660928,25.94281702154912,141.99089341999647,18134.01328576312,1.2567029315809053,18.0,939.9805197055488,20643555.743849196,1656.533999974717,472.0
474,16545.84813826597,989.9824682909866,30.688422314117567,177.5945044393059,23718.131637054954,1.418851291778451,18.0,963.0045579588145,21629061.827650268,1662.3799999745788,474.0
480,16103.783801101394,815.5702149875106,32.239505260969544,206.00063129225526,19620.076647414036,2.2065630102985727,18.0,785.1680089535747,14610734.02866804,1677.7819999742146,480.0
482,15951.131334400514,880.8441625365105,30.66264041733432,189.01756130499498,20866.90746137237,1.7939859436669245,18.0,852.0942191802717,17091906.726236433,1683.89799997407,482.0
484,15435.009211245813,901.5285652220178,48.666982238896125,247.64978827937847,21245.611115210482,2.762451191854289,18.0,865.6327469302129,17617318.409969274,1689.6179999739347,484.0
487,16723.336672286714,947.2603528374622,29.363989069771666,151.3927184582591,17069.80977523672,1.4945214425657452,18.0,916.1536163955714,19647753.610922128,1700.4559999736784,487.0
490,17960.449276531253,965.1228300260426,25.88420252672213,157.3444933351699,21732.43360626405,1.2557705862398312,18.0,939.2392420917932,20612206.40963371,1711.1679999734251,490.0
496,15473.545457718947,884.8016313839918,24.08689620716218,176.83325016318668,24189.496814934166,1.3809800077154595,19.0,861.1349008045332,17441886.24932296,1736.0719999728362,496.0
498,17119.83691497916,982.685328050224,27.433130050746243,154.2330355079373,20456.626687393724,1.2883452346115014,19.0,955.2201806173293,21293306.57168043,1744.0799999726469,498.0
501,16174.510798889572,814.2133775320414,40.621482202723726,266.7950927782511,23688.80001166321,2.793942367817701,19.0,783.1557973144642,14539126.74456934,1751.6779999724672,501.0
503,15652.725549026529,874.9705688114992,32.71852633193399,188.44844530529133,19099.28400550912,1.949988385466837,19.0,843.92857648107,16778831.38986031,1757.7159999723244,503.0
505,15309.97823407566,954.5882156326945,56.503291369788684,284.4591451108205,25661.13823765334,2.856330203374505,19.0,919.3949004808456,19781778.487317387,1763.6879999721832,505.0
507,16743.130682619063,949.5889996320285,27.929922283471278,167.24787709179583,21638.599627257685,1.402345821472423,19.0,922.6437909548088,19916572.542816624,1771.647999971995,507.0
513,17109.026297872962,955.3059953538619,24.22923910513174,139.12741157630808,18272.07612479782,1.2030655562249022,19.0,927.9950204408646,20139583.399894383,1787.8719999716113,513.0
515,17896.565960374402,1024.7755743983482,26.773621127765274,145.6563523666865,20619.36218293354,1.1560508451481284,19.0,997.7498585318622,23159553.26717026,1794.905999971445,515.0
517,18002.156124158606,1146.645129679953,106.5055148448477,327.6484595409517,23838.4277526755,3.8319244075384877,19.0,1096.5138827341684,27794263.017120324,1800.6499999713092,517.0
523,16112.452906006489,856.2542714263066,60.49310438655023,370.15124041807195,28960.145595849564,3.7923307935824675,20.0,821.9764012949299,15951431.370100696,1826.8699999706892,523.0
529,16540.097400314986,995.5169393832473,29.989543099563264,174.80572771114348,23901.640941466365,1.3701810654333282,20.0,968.9505625287067,21887284.721803457,1843.0839999703057,529.0
531,15935.335393830313,824.9875578991729,23.947378625281917,156.22356674437955,16912.55906516208,1.593638415788557,20.0,796.7657006624115,15026858.281043874,1848.8719999701689,531.0
533,17115.8825244353,954.7276412187514,29.481835493308186,164.20740959153665,19994.407241192133,1.4701735870137678,20.0,925.9281871032649,20053302.38124602,1856.2159999699952,533.0
540,17617.90519068941,1024.6320689049212,26.885870164804075,143.4582190295171,19965.399175569517,1.162336245848989,20.0,997.1097949739349,23130888.55382481,1874.955999969552,540.0
542,17446.975896501604,971.9112611269437,35.87674728698775,256.27673006998236,36310.799231466146,1.7085327908121792,20.0,948.3363594547512,20998571.101426244,1881.1579999694054,542.0
547,14200.43436996764,932.6524622579843,67.69822081711973,291.7193575047688,20935.73377491386,3.6430095826302598,21.0,890.003762287558,18583047.692189023,1902.95799996889,547.0
549,15637.85054290559,1002.6116684124938,53.55203393032925,357.0571830223124,43149.957709299386,2.4118474663487106,21.0,976.1900715855197,22203739.94521367,1910.8779999687026,549.0
557,16596.839049961087,954.4092511645918,164.711909011786,511.6410748686152,19444.149261468156,8.952764986942768,21.0,885.3806153605979,18397881.4647778,1932.6499999681878,557.0
559,17205.685861088157,908.2951003351174,26.94203558809183,180.84400185031694,23580.458072497375,1.4721898578846506,21.0,882.9437937502838,18300652.897313196,1939.495999968026,559.0
569,17196.351758120018,986.3469296867771,30.164691988742653,178.3830494057112,24160.578470336728,1.4034970337532628,21.0,959.8462479262326,21492522.7936361,1964.7539999674286,569.0
571,17219.274030764096,881.3738398485283,47.20637719798361,318.5517173455508,31696.27127070932,2.75982590239741,21.0,852.429908996685,17104838.807758234,1971.245999967275,571.0
573,14707.158289756311,826.694985452555,45.23030837757643,273.8718146582899,22734.305008628566,3.0356291319336144,22.0,793.2419757403609,14899813.650413198,1986.559999966913,573.0
575,15044.499526340576,964.7381015295839,63.08420188299377,443.8880211655592,46513.7322101164,3.0738874650892205,22.0,937.1176371696939,20522612.684899554,1993.243999966755,575.0
583,15520.568126866989,959.7412217139492,62.843024600958046,280.3639391776204,22585.560681230312,3.1716007576304297,22.0,920.1795745911941,19814292.34110456,2015.947999966218,583.0
585,17292.755346675407,948.400990770892,26.675786760576425,136.878466225998,15776.525387275602,1.3536959502215862,22.0,917.5610026829305,19705892.417133898,2024.157999966024,585.0
587,16856.61718858102,965.1872493932399,30.01521826956943,158.50929976699234,18828.68473063349,1.4681974108772669,22.0,935.2424074906809,20443584.798065376,2030.0799999658839,587.0
590,16495.420014096733,1000.7035350090604,111.62286520022354,407.76201052544826,23868.924399431446,5.304106305320345,22.0,949.4148668141179,21044613.130822614,2037.8499999657001,590.0
595,16851.281295656627,971.6068751716109,62.48395384977518,398.4214266972427,40624.59692763545,3.013123683453327,22.0,942.1930855150976,20737268.168880016,2052.439999965355,595.0
597,16635.33803678074,869.847412384045,68.15218451500319,286.26135557668755,17363.356216948963,4.263689313418882,22.0,822.8596984160326,15984322.380270874,2058.4219999652137,597.0
601,14671.940209041351,977.4740554811883,58.69093857218521,377.67911898200924,40534.86846934554,2.7915974119463143,23.0,948.935472415852,21024141.346823223,2080.8359999646837,601.0
603,15727.319815902072,977.4068459232228,151.7755839625677,451.4162156059999,18703.256971305073,7.828252339218449,23.0,909.8446744937278,19388182.366349287,2087.451999964527,603.0
606,16708.140306216967,910.5754545339611,28.334456637545173,200.01289856883153,26796.555731157696,1.5373991511903133,23.0,886.1872841918299,18430123.768188342,2097.105999964299,606.0
610,17623.4749113008,988.6240008809789,29.874124177350694,183.69192782198772,25820.047944111637,1.380903617890737,23.0,963.1128335029254,21633750.386563517,2109.835999963998,610.0
612,17823.633634848065,946.4085920967387,27.546677999644402,218.58471989179478,34751.26962289048,1.3754901633991805,23.0,925.292646148823,20026808.429927018,2116.265999963846,612.0
614,16795.692040573078,994.3905861488835,60.6197618736848,264.3675774148794,22938.31702341237,2.8433645907852,23.0,955.8349741562663,21319728.771379456,2121.463999963723,614.0
624,16272.42911095074,924.355789254271,60.71378750662938,287.50827375364435,22592.794827883557,3.299356341499629,23.0,885.4763540514668,18401706.642888308,2148.489999963084,624.0
627,14715.235493253143,956.1882221659081,56.70549291181367,328.4940328212589,32355.056735652768,2.8344421987411286,24.0,924.7901671943704,20005873.79661455,2168.0759999626207,627.0
629,14996.891750376994,918.2320155188701,56.32258400356466,314.51962192396104,27968.424012062238,3.0667215873206737,24.0,884.5755464675462,18365731.090957116,2174.701999962464,629.0
631,15173.78520714376,937.3031687780077,73.42804272678613,296.91319682868743,19920.088116820603,3.9363260618829243,24.0,891.7680355307405,18653953.34950026,2181.297999962308,631.0
633,16927.657613001928,895.542013963351,29.858868149918454,246.07606895857805,34879.57136890881,1.665289173326576,24.0,873.5981872901634,17930140.079078566,2189.509999962114,633.0
636,17867.723422729556,931.2785086962554,28.79784968924179,188.14014878617738,24786.402049310742,1.4983920131761015,24.0,905.71417082799,19219169.24009743,2199.191999961885,636.0
638,18092.7328198854,953.5083524959288,26.001977202866193,165.9615355088166,23210.903160872207,1.2899884320826713,24.0,928.405768429708,20156752.22830201,2205.691999961731,638.0
640,17033.79048711963,947.3485926713254,29.18543070695659,157.412937313299,18438.759459778074,1.4812094588534097,24.0,917.5099909659729,19703783.642827097,2210.907999961608,640.0
642,15418.460254778709,940.886099468706,58.84590143178259,346.5934529065731,32733.272602602705,3.0400171833622447,24.0,909.0862796136914,19357095.003883928,2215.8359999614913,642.0
644,17060.886500518835,937.7306423087398,27.882872595703162,172.19197567293736,22251.81806976005,1.434079247032979,24.0,911.1816971552337,19443048.669305477,2223.3479999613137,644.0
648,16559.297580324404,945.1896927450182,256.3367732646886,748.2230458091766,19058.83200880159,14.792983563500801,24.0,858.209857850166,17328267.29404043,2233.269999961079,648.0
650,16847.399981462095,1018.7578543157971,31.693495596344544,160.6646865775066,20338.828795797453,1.391532629010061,24.0,989.1516069114035,22775962.945900425,2239.8399999609237,650.0
652,14628.82033084386,944.737060338494,65.38499506645574,375.7183834498576,33417.073904846635,3.360201126548671,25.0,911.561665413915,19458655.182826504,2255.3699999605565,652.0
654,15107.713362086673,967.038975279042,57.73368679580346,321.60011075079376,31410.293952827622,2.8261311659176904,25.0,934.8846123823467,20428523.45002763,2262.1439999603963,654.0
656,14643.75403645049,929.0926269350656,68.85059838750729,355.0980066187534,27971.178518854922,3.690026817533908,25.0,891.8826209024884,18658563.14657383,2268.041999960257,656.0
658,16770.394947268254,928.4212340167282,29.516126571030615,208.95332442909918,28790.36047966735,1.5400383761045724,25.0,904.4070743384943,19165838.351177815,2276.4259999600586,658.0
661,16780.964415001883,1174.2821357538674,116.31896023340218,586.8729584834124,53730.682154717506,3.8854541792116075,25.0,1139.3861603655846,29937030.49073257,2284.983999959856,661.0
663,18414.859210303184,1011.3703894141693,27.78879107623833,157.17422831316426,22136.490142177394,1.230522339513697,25.0,984.7973207915094,22582922.864464596,2292.9979999596667,663.0
664,18093.52953177907,988.6417896941366,26.851918352829003,168.8372402579841,24895.76489319265,1.2389775558646718,25.0,964.0105548276,21672643.080357727,2295.7599999596014,664.0